<?xml version="1.0" encoding="UTF-8"?>
<!-- Generated by org.testng.reporters.JUnitReportReporter -->
<testsuite hostname="DESKTOP-KD3NU29" failures="1" tests="6" name="testCases.TC_003_LoginDataDrivenTest" time="53.759" errors="1" timestamp="2023-08-12T16:10:39 IST" skipped="0">
  <testcase classname="testCases.TC_003_LoginDataDrivenTest" name="tearDown" time="0.081">
    <error message="Unable to establish websocket connection to http://127.0.0.1:4092/devtools/browser/e9e0fea5-0138-4d2e-9d7b-e3dd8874ab49
Build info: version: &#039;4.10.0&#039;, revision: &#039;c14d967899&#039;
System info: os.name: &#039;Windows 10&#039;, os.arch: &#039;amd64&#039;, os.version: &#039;10.0&#039;, java.version: &#039;17.0.7&#039;
Driver info: driver.version: FirefoxDriver" type="org.openqa.selenium.remote.http.ConnectionFailedException">
      <![CDATA[org.openqa.selenium.remote.http.ConnectionFailedException: Unable to establish websocket connection to http://127.0.0.1:4092/devtools/browser/e9e0fea5-0138-4d2e-9d7b-e3dd8874ab49
Build info: version: '4.10.0', revision: 'c14d967899'
System info: os.name: 'Windows 10', os.arch: 'amd64', os.version: '10.0', java.version: '17.0.7'
Driver info: driver.version: FirefoxDriver
at org.openqa.selenium.remote.http.netty.NettyWebSocket.<init>(NettyWebSocket.java:116)
at org.openqa.selenium.remote.http.netty.NettyWebSocket.lambda$create$3(NettyWebSocket.java:147)
at org.openqa.selenium.remote.http.netty.NettyClient.openSocket(NettyClient.java:105)
at org.openqa.selenium.devtools.Connection.<init>(Connection.java:83)
at org.openqa.selenium.firefox.FirefoxDriver.maybeGetDevTools(FirefoxDriver.java:305)
at org.openqa.selenium.remote.RemoteWebDriver.quit(RemoteWebDriver.java:439)
at org.openqa.selenium.firefox.FirefoxDriver.quit(FirefoxDriver.java:363)
at testBase.BaseClass.tearDown(BaseClass.java:75)
at java.base/jdk.internal.reflect.NativeMethodAccessorImpl.invoke0(Native Method)
at java.base/jdk.internal.reflect.NativeMethodAccessorImpl.invoke(NativeMethodAccessorImpl.java:77)
at java.base/jdk.internal.reflect.DelegatingMethodAccessorImpl.invoke(DelegatingMethodAccessorImpl.java:43)
at java.base/java.lang.reflect.Method.invoke(Method.java:568)
at org.testng.internal.invokers.MethodInvocationHelper.invokeMethod(MethodInvocationHelper.java:139)
at org.testng.internal.invokers.MethodInvocationHelper.invokeMethodConsideringTimeout(MethodInvocationHelper.java:69)
at org.testng.internal.invokers.ConfigInvoker.invokeConfigurationMethod(ConfigInvoker.java:390)
at org.testng.internal.invokers.ConfigInvoker.invokeConfigurations(ConfigInvoker.java:325)
at org.testng.internal.invokers.TestMethodWorker.invokeAfterClassConfigurations(TestMethodWorker.java:229)
at org.testng.internal.invokers.TestMethodWorker.invokeAfterClassMethods(TestMethodWorker.java:215)
at org.testng.internal.invokers.TestMethodWorker.run(TestMethodWorker.java:131)
at java.base/java.util.ArrayList.forEach(ArrayList.java:1511)
at org.testng.TestRunner.privateRun(TestRunner.java:848)
at org.testng.TestRunner.run(TestRunner.java:621)
at org.testng.SuiteRunner.runTest(SuiteRunner.java:443)
at org.testng.SuiteRunner.runSequentially(SuiteRunner.java:437)
at org.testng.SuiteRunner.privateRun(SuiteRunner.java:397)
at org.testng.SuiteRunner.run(SuiteRunner.java:336)
at org.testng.SuiteRunnerWorker.runSuite(SuiteRunnerWorker.java:52)
at org.testng.SuiteRunnerWorker.run(SuiteRunnerWorker.java:95)
at org.testng.TestNG.runSuitesSequentially(TestNG.java:1280)
at org.testng.TestNG.runSuitesLocally(TestNG.java:1200)
at org.testng.TestNG.runSuites(TestNG.java:1114)
at org.testng.TestNG.run(TestNG.java:1082)
at org.testng.remote.AbstractRemoteTestNG.run(AbstractRemoteTestNG.java:115)
at org.testng.remote.RemoteTestNG.initAndRun(RemoteTestNG.java:251)
at org.testng.remote.RemoteTestNG.main(RemoteTestNG.java:77)
]]>
    </error>
  </testcase> <!-- tearDown -->
  <testcase classname="testCases.TC_003_LoginDataDrivenTest" name="test_LoginDDT" time="5.819">
    <failure message="expected [true] but found [false]" type="java.lang.AssertionError">
      <![CDATA[java.lang.AssertionError: expected [true] but found [false]
at org.testng.Assert.fail(Assert.java:111)
at org.testng.Assert.failNotEquals(Assert.java:1578)
at org.testng.Assert.assertTrue(Assert.java:57)
at org.testng.Assert.assertTrue(Assert.java:67)
at testCases.TC_003_LoginDataDrivenTest.test_LoginDDT(TC_003_LoginDataDrivenTest.java:45)
at java.base/jdk.internal.reflect.NativeMethodAccessorImpl.invoke0(Native Method)
at java.base/jdk.internal.reflect.NativeMethodAccessorImpl.invoke(NativeMethodAccessorImpl.java:77)
at java.base/jdk.internal.reflect.DelegatingMethodAccessorImpl.invoke(DelegatingMethodAccessorImpl.java:43)
at java.base/java.lang.reflect.Method.invoke(Method.java:568)
at org.testng.internal.invokers.MethodInvocationHelper.invokeMethod(MethodInvocationHelper.java:139)
at org.testng.internal.invokers.TestInvoker.invokeMethod(TestInvoker.java:664)
at org.testng.internal.invokers.TestInvoker.invokeTestMethod(TestInvoker.java:227)
at org.testng.internal.invokers.MethodRunner.runInSequence(MethodRunner.java:50)
at org.testng.internal.invokers.TestInvoker$MethodInvocationAgent.invoke(TestInvoker.java:957)
at org.testng.internal.invokers.TestInvoker.invokeTestMethods(TestInvoker.java:200)
at org.testng.internal.invokers.TestMethodWorker.invokeTestMethods(TestMethodWorker.java:148)
at org.testng.internal.invokers.TestMethodWorker.run(TestMethodWorker.java:128)
at java.base/java.util.ArrayList.forEach(ArrayList.java:1511)
at org.testng.TestRunner.privateRun(TestRunner.java:848)
at org.testng.TestRunner.run(TestRunner.java:621)
at org.testng.SuiteRunner.runTest(SuiteRunner.java:443)
at org.testng.SuiteRunner.runSequentially(SuiteRunner.java:437)
at org.testng.SuiteRunner.privateRun(SuiteRunner.java:397)
at org.testng.SuiteRunner.run(SuiteRunner.java:336)
at org.testng.SuiteRunnerWorker.runSuite(SuiteRunnerWorker.java:52)
at org.testng.SuiteRunnerWorker.run(SuiteRunnerWorker.java:95)
at org.testng.TestNG.runSuitesSequentially(TestNG.java:1280)
at org.testng.TestNG.runSuitesLocally(TestNG.java:1200)
at org.testng.TestNG.runSuites(TestNG.java:1114)
at org.testng.TestNG.run(TestNG.java:1082)
at org.testng.remote.AbstractRemoteTestNG.run(AbstractRemoteTestNG.java:115)
at org.testng.remote.RemoteTestNG.initAndRun(RemoteTestNG.java:251)
at org.testng.remote.RemoteTestNG.main(RemoteTestNG.java:77)
]]>
    </failure>
  </testcase> <!-- test_LoginDDT -->
  <testcase classname="testCases.TC_003_LoginDataDrivenTest" name="test_LoginDDT" time="12.085"/>
  <testcase classname="testCases.TC_003_LoginDataDrivenTest" name="test_LoginDDT" time="11.779"/>
  <testcase classname="testCases.TC_003_LoginDataDrivenTest" name="test_LoginDDT" time="11.966"/>
  <testcase classname="testCases.TC_003_LoginDataDrivenTest" name="test_LoginDDT" time="12.029"/>
</testsuite> <!-- testCases.TC_003_LoginDataDrivenTest -->
